<mujoco model="ur5e">
  <compiler angle="radian" meshdir="assets" autolimits="true" />

  <option integrator="implicitfast" />

  <default>
    <default class="ur5e">
      <material specular="0.5" shininess="0.25" />
      <joint axis="0 1 0" range="-6.28319 6.28319" armature="0.1" />
      <general gaintype="fixed" biastype="affine" ctrlrange="-6.2831 6.2831" gainprm="2000"
        biasprm="0 -2000 -400" forcerange="-150 150" />
      <default class="size3">
        <default class="size3_limited">
          <joint range="-3.1415 3.1415" />
          <general ctrlrange="-3.1415 3.1415" />
        </default>
      </default>
      <default class="size1">
        <general gainprm="500" biasprm="0 -500 -100" forcerange="-28 28" />
      </default>
      <default class="visual">
        <geom type="mesh" contype="0" conaffinity="0" group="2" />
      </default>
      <default class="collision">
        <geom type="capsule" group="3" />
        <default class="eef_collision">
          <geom type="cylinder" />
        </default>
      </default>
      <site size="0.001" rgba="0.5 0.5 0.5 0.3" group="4" />
    </default>
    <default class="2f85">
      <mesh scale="0.001 0.001 0.001" />
      <general biastype="affine" />
      <site type="sphere" rgba="0.9 0.9 0.9 1" size="0.005" group="4" />
      <joint axis="1 0 0" />
      <default class="driver">
        <joint range="0 0.8" armature="0.005" damping="0.1" solimplimit="0.95 0.99 0.001"
          solreflimit="0.005 1" />
      </default>
      <default class="follower">
        <joint range="-0.872664 0.872664" pos="0 -0.018 0.0065" solimplimit="0.95 0.99 0.001"
          solreflimit="0.005 1" stiffness="1" />
      </default>
      <default class="spring_link">
        <joint range="-0.29670597283 0.8" stiffness="0.05" springref="2.62" damping="0.00125" />
      </default>
      <default class="coupler">
        <joint range="-1.57 0" solimplimit="0.95 0.99 0.001" solreflimit="0.005 1" />
      </default>
      <default class="2f85/visual">
        <geom type="mesh" contype="0" conaffinity="0" group="2" />
      </default>
      <default class="2f85/collision">
        <geom type="mesh" group="3" />
      </default>
    </default>

    <default class="custom_gripper">
      <default class="custom_gripper/visual">
        <geom type="mesh" contype="0" conaffinity="0" group="2" />
      </default>
      <default class="custom_gripper/collision">
        <geom type="mesh" group="4" />
      </default>
      <default class="hook">
        <position kp="500" kv="50" forcerange="-28 28" />
      </default>
    </default>

  </default>

  <asset>
    <material class="ur5e" name="black" rgba="0.033 0.033 0.033 1" />
    <material class="ur5e" name="jointgray" rgba="0.278 0.278 0.278 1" />
    <material class="ur5e" name="linkgray" rgba="0.82 0.82 0.82 1" />
    <material class="ur5e" name="urblue" rgba="0.49 0.678 0.8 1" />

    <mesh file="ur5e/base_0.obj" />
    <mesh file="ur5e/base_1.obj" />
    <mesh file="ur5e/shoulder_0.obj" />
    <mesh file="ur5e/shoulder_1.obj" />
    <mesh file="ur5e/shoulder_2.obj" />
    <mesh file="ur5e/upperarm_0.obj" />
    <mesh file="ur5e/upperarm_1.obj" />
    <mesh file="ur5e/upperarm_2.obj" />
    <mesh file="ur5e/upperarm_3.obj" />
    <mesh file="ur5e/forearm_0.obj" />
    <mesh file="ur5e/forearm_1.obj" />
    <mesh file="ur5e/forearm_2.obj" />
    <mesh file="ur5e/forearm_3.obj" />
    <mesh file="ur5e/wrist1_0.obj" />
    <mesh file="ur5e/wrist1_1.obj" />
    <mesh file="ur5e/wrist1_2.obj" />
    <mesh file="ur5e/wrist2_0.obj" />
    <mesh file="ur5e/wrist2_1.obj" />
    <mesh file="ur5e/wrist2_2.obj" />
    <mesh file="ur5e/wrist3.obj" />
    <material name="2f85/gray" rgba="0.4627 0.4627 0.4627 1" />
    <material name="2f85/black" rgba="0.149 0.149 0.149 1" />

    <mesh class="2f85" file="2f85/base_mount.stl" />
    <mesh class="2f85" file="2f85/base.stl" />
    <mesh class="2f85" file="2f85/driver.stl" />
    <mesh class="2f85" file="2f85/coupler.stl" />
    <mesh class="2f85" file="2f85/follower.stl" />
    <mesh class="2f85" file="2f85/pad.stl" />
    <mesh class="2f85" file="2f85/silicone_pad.stl" />
    <mesh class="2f85" file="2f85/spring_link.stl" />

    <mesh name="left_base_link" file="2f85/custom_gripper/right_base_link.STL" />
    <mesh name="left_base_link_collision" file="2f85/custom_gripper/right_collision.STL"
      scale="0.001 0.001 0.001" />

    <mesh name="right_base_link" file="2f85/custom_gripper/left_base_link.STL" />
    <mesh name="right_base_link_collision"
      file="2f85/custom_gripper/left_base_link_collision_coacd.stl" />
    <mesh name="hook_link" file="2f85/custom_gripper/hook_link.STL" />
    <mesh name="hook_link_collision" file="2f85/custom_gripper/hook_link_collision.STL" />
  </asset>

  <worldbody>
    <light name="light1" pos="0 0 2" dir="0 0 -1" diffuse="1 1 1" specular="0.5 0.5 0.5" />
    <body name="ur5e/base" childclass="ur5e" quat="1 0 0 0" pos="0 0 0">
      <inertial mass="4.0" pos="0 0 0" diaginertia="0.00443333156 0.00443333156 0.0072" />
      <geom mesh="base_0" material="black" class="visual" />
      <geom mesh="base_1" material="jointgray" class="visual" />
      <body name="shoulder_link" pos="0 0 0.163" quat="0 0 0 1">
        <inertial mass="3.7" pos="0 0 0" diaginertia="0.0102675 0.0102675 0.00666" />
        <joint name="shoulder_pan_joint" class="size3" axis="0 0 1" damping="1" range="-0.1 3.18" />
        <geom mesh="shoulder_0" material="urblue" class="visual" />
        <geom mesh="shoulder_1" material="black" class="visual" />
        <geom mesh="shoulder_2" material="jointgray" class="visual" />
        <geom class="collision" size="0.06 0.06" pos="0 0 -0.04" />
        <body name="upper_arm_link" pos="0 0.138 0" quat="1 0 0 0">
          <inertial mass="8.393" pos="0 0 0.2125" diaginertia="0.133886 0.133886 0.0151074" />
          <joint name="shoulder_lift_joint" class="size3" range="0 1.58" />
          <geom mesh="upperarm_0" material="linkgray" class="visual" />
          <geom mesh="upperarm_1" material="black" class="visual" />
          <geom mesh="upperarm_2" material="jointgray" class="visual" />
          <geom mesh="upperarm_3" material="urblue" class="visual" />
          <geom class="collision" pos="0 -0.04 0" quat="1 1 0 0" size="0.06 0.06" />
          <geom class="collision" size="0.05 0.2" pos="0 0 0.2" />
          <body name="forearm_link" pos="0 -0.131 0.425">
            <inertial mass="2.275" pos="0 0 0.196" diaginertia="0.0311796 0.0311796 0.004095" />
            <joint name="elbow_joint" class="size3_limited" range="0 3.15" />
            <geom mesh="forearm_0" material="urblue" class="visual" />
            <geom mesh="forearm_1" material="linkgray" class="visual" />
            <geom mesh="forearm_2" material="black" class="visual" />
            <geom mesh="forearm_3" material="jointgray" class="visual" />
            <geom class="collision" pos="0 0.08 0" quat="1 1 0 0" size="0.055 0.06" />
            <geom class="collision" size="0.038 0.19" pos="0 0 0.2" />
            <body name="wrist_1_link" pos="0 0 0.392" quat="1 0 0 0">
              <inertial mass="1.219" pos="0 0.127 0" diaginertia="0.0025599 0.0025599 0.0021942" />
              <joint name="wrist_1_joint" class="size1" range="-1.20 3.14" />
              <geom mesh="wrist1_0" material="black" class="visual" />
              <geom mesh="wrist1_1" material="urblue" class="visual" />
              <geom mesh="wrist1_2" material="jointgray" class="visual" />
              <geom class="collision" pos="0 0.05 0" quat="1 1 0 0" size="0.04 0.07" />
              <body name="wrist_2_link" pos="0 0.127 0">
                <inertial mass="1.219" pos="0 0 0.1" diaginertia="0.0025599 0.0025599 0.0021942" />
                <joint name="wrist_2_joint" axis="0 0 1" class="size1" range="-3.14 3.14" />
                <geom mesh="wrist2_0" material="black" class="visual" />
                <geom mesh="wrist2_1" material="urblue" class="visual" />
                <geom mesh="wrist2_2" material="jointgray" class="visual" />
                <geom class="collision" size="0.04 0.06" pos="0 0 0.04" />
                <geom class="collision" pos="0 0.02 0.1" quat="1 1 0 0" size="0.04 0.04" />
                <body name="wrist_3_link" pos="0 0 0.1" quat="1 0 0 0">
                  <inertial mass="0.1889" pos="0 0.0771683 0" quat="1 0 0 1"
                    diaginertia="0.000132134 9.90863e-05 9.90863e-05" />
                  <joint name="wrist_3_joint" class="size1" />
                  <geom material="linkgray" mesh="wrist3" class="visual" />
                  <geom class="eef_collision" pos="0 0.08 0" quat="1 1 0 0" size="0.04 0.02" />
                  <body name="attachment" pos="0 0.1 0" quat="1 -1 0 0">
                    <site name="attachment_site" rgba="1 0 0 1" size="0.01" group="1" />
                  </body>
                </body>
              </body>
            </body>
          </body>
        </body>
      </body>
    </body>
  </worldbody>

  <actuator>
    <general class="size3" name="shoulder_pan" joint="shoulder_pan_joint" forcerange="-18 18"
      forcelimited="true" />
    <general class="size3" name="shoulder_lift" joint="shoulder_lift_joint" />
    <general class="size3_limited" name="elbow" joint="elbow_joint" />
    <general class="size1" name="wrist_1" joint="wrist_1_joint" />
    <general class="size1" name="wrist_2" joint="wrist_2_joint" />
    <general class="size1" name="wrist_3" joint="wrist_3_joint" />
  </actuator>
</mujoco>