<mujoco model="ur5e">
  <compiler angle="radian" meshdir="assets" texturedir="assets" />

  <option integrator="implicitfast" />

  <default>

    <default class="ur5e">
      <default class="visual">
        <geom type="mesh" contype="0" conaffinity="0" group="2" />
      </default>
      <default class="collision">
        <geom type="capsule" group="3" />
        <default class="eef_collision">
          <geom type="cylinder" />
        </default>
      </default>
      <joint axis="0 1 0" range="-6.28319 6.28319" />
      <default class="joint_limited">
        <joint range="-3.1415 3.1415" />
      </default>
      <default class="position">
        <position ctrlrange="-6.2831 6.2831" kp="2000" kv="200" forcerange="-150 150" />
        <default class="position_limited">
          <position ctrlrange="-3.1415 3.1415" />
        </default>
        <default class="position_small">
          <position kp="500" kv="50" forcerange="-28 28" />
        </default>
      </default>
    </default>

    <default class="2f85">
      <mesh scale="0.001 0.001 0.001" />
      <general biastype="affine" />
      <site type="sphere" rgba="0.9 0.9 0.9 1" size="0.005" group="4" />
      <joint axis="1 0 0" />
      <default class="driver">
        <joint range="0 0.8" armature="0.005" damping="0.1" solimplimit="0.95 0.99 0.001"
          solreflimit="0.005 1" />
      </default>
      <default class="follower">
        <joint range="-0.872664 0.872664" pos="0 -0.018 0.0065" solimplimit="0.95 0.99 0.001"
          solreflimit="0.005 1" />
      </default>
      <default class="spring_link">
        <joint range="-0.29670597283 0.8" stiffness="0.05" springref="2.62" damping="0.00125" />
      </default>
      <default class="coupler">
        <joint range="-1.57 0" solimplimit="0.95 0.99 0.001" solreflimit="0.005 1" />
      </default>
      <default class="2f85/visual">
        <geom type="mesh" contype="0" conaffinity="0" group="2" />
      </default>
      <default class="2f85/collision">
        <geom type="mesh" group="3" />
      </default>
    </default>

    <default class="custom_gripper">
      <default class="custom_gripper/visual">
        <geom type="mesh" contype="0" conaffinity="0" group="2" />
      </default>
      <default class="custom_gripper/collision">
        <geom type="mesh" group="3" />
      </default>
      <default class="hook">
        <position kp="500" kv="50" forcerange="-28 28" />
      </default>
    </default>

  </default>

  <asset>
    <material name="black" rgba="0.033 0.033 0.033 1" />
    <material name="jointgray" rgba="0.278 0.278 0.278 1" />
    <material name="linkgray" rgba="0.82 0.82 0.82 1" />
    <material name="urblue" rgba="0.49 0.678 0.8 1" />
    <material name="white" rgba="1 1 1 1" />
    <material name="off_white" rgba="0.901961 0.921569 0.929412 1" />
    <material name="dark_grey" rgba="0.25 0.25 0.25 1" />
    <material name="green" rgba="0 1 0 1" />
    <material name="light_blue" rgba="0.039216 0.541176 0.780392 1" />
    <material name="metal" rgba="0.58 0.58 0.58 1" />
    <material name="silicone" rgba="0.1882 0.1882 0.1882 1" />
    <material name="gray" rgba="0.4627 0.4627 0.4627 1" />
    <material name="2f85/black" rgba="0.149 0.149 0.149 1" />

    <mesh file="base_0.obj" />
    <mesh file="base_1.obj" />
    <mesh file="shoulder_0.obj" />
    <mesh file="shoulder_1.obj" />
    <mesh file="shoulder_2.obj" />
    <mesh file="upperarm_0.obj" />
    <mesh file="upperarm_1.obj" />
    <mesh file="upperarm_2.obj" />
    <mesh file="upperarm_3.obj" />
    <mesh file="forearm_0.obj" />
    <mesh file="forearm_1.obj" />
    <mesh file="forearm_2.obj" />
    <mesh file="forearm_3.obj" />
    <mesh file="wrist1_0.obj" />
    <mesh file="wrist1_1.obj" />
    <mesh file="wrist1_2.obj" />
    <mesh file="wrist2_0.obj" />
    <mesh file="wrist2_1.obj" />
    <mesh file="wrist2_2.obj" />
    <mesh file="wrist3.obj" />

    <mesh class="2f85" file="base_mount.stl" />
    <mesh class="2f85" file="base.stl" />
    <mesh class="2f85" file="driver.stl" />
    <mesh class="2f85" file="coupler.stl" />
    <mesh class="2f85" file="follower.stl" />
    <mesh class="2f85" file="pad.stl" />
    <mesh class="2f85" file="silicone_pad.stl" />
    <mesh class="2f85" file="spring_link.stl" />

    <mesh name="left_base_link" file="custom_gripper/right_base_link.STL" />
    <mesh name="left_base_link_collision" file="custom_gripper/right_collision.STL" scale="0.001 0.001 0.001"/>

    <mesh name="right_base_link" file="custom_gripper/left_base_link.STL" />
    <mesh name="right_base_link_collision" file="custom_gripper/left_base_link_collision_coacd.stl" />
    <mesh name="hook_link" file="custom_gripper/hook_link.STL" />
    <mesh name="hook_link_collision" file="custom_gripper/hook_link_collision.STL" />

  </asset>

  <worldbody>
    <light name="light1" pos="0 0 10" dir="0 0 -1" diffuse="1 1 1" specular="0.3 0.3 0.3" />
    <light name="light2" pos="1 1 2" dir="-1 -1 -2" diffuse="0.7 0.7 0.7" specular="0.2 0.2 0.2" />
    <body name="ur5e/base" quat="1 0 0 1" childclass="ur5e" pos="0 -0.12075 0.3">
      <inertial mass="4" pos="0 0 0" diaginertia="0.00443333156 0.00443333156 0.0072" />
      <geom mesh="base_0" material="black" class="visual" />
      <geom mesh="base_1" material="jointgray" class="visual" />
      <body name="shoulder_link" pos="0 0 0.163">
        <inertial mass="3.7" pos="0 0 0" diaginertia="0.0102675 0.0102675 0.00666" />
        <joint name="shoulder_pan_joint" axis="0 0 1" />
        <site name="shoulder_pan_joint" />
        <geom mesh="shoulder_0" material="urblue" class="visual" />
        <geom mesh="shoulder_1" material="black" class="visual" />
        <geom mesh="shoulder_2" material="jointgray" class="visual" />
        <geom class="collision" size="0.06 0.06" pos="0 0 -0.04" />
        <body name="upper_arm_link" pos="0 0.138 0" quat="1 0 1 0">
          <inertial mass="8.393" pos="0 0 0.2125" diaginertia="0.133886 0.133886 0.0151074" />
          <joint name="shoulder_lift_joint" />
          <site name="shoulder_lift_joint" />
          <geom mesh="upperarm_0" material="linkgray" class="visual" />
          <geom mesh="upperarm_1" material="black" class="visual" />
          <geom mesh="upperarm_2" material="jointgray" class="visual" />
          <geom mesh="upperarm_3" material="urblue" class="visual" />
          <geom class="collision" pos="0 -0.04 0" quat="1 1 0 0" size="0.06 0.06" />
          <geom class="collision" size="0.05 0.2" pos="0 0 0.2" />
          <body name="forearm_link" pos="0 -0.131 0.425">
            <inertial mass="2.275" pos="0 0 0.196" diaginertia="0.0311796 0.0311796 0.004095" />
            <joint name="elbow_joint" class="joint_limited" />
            <site name="elbow_joint" />
            <geom mesh="forearm_0" material="urblue" class="visual" />
            <geom mesh="forearm_1" material="linkgray" class="visual" />
            <geom mesh="forearm_2" material="black" class="visual" />
            <geom mesh="forearm_3" material="jointgray" class="visual" />
            <geom class="collision" pos="0 0.08 0" quat="1 1 0 0" size="0.055 0.06" />
            <geom class="collision" size="0.038 0.19" pos="0 0 0.2" />
            <body name="wrist_1_link" pos="0 0 0.392" quat="1 0 1 0">
              <inertial mass="1.219" pos="0 0.127 0" diaginertia="0.0025599 0.0025599 0.0021942" />
              <joint name="wrist_1_joint" />
              <site name="wrist_1_joint" />
              <geom mesh="wrist1_0" material="black" class="visual" />
              <geom mesh="wrist1_1" material="urblue" class="visual" />
              <geom mesh="wrist1_2" material="jointgray" class="visual" />
              <geom class="collision" pos="0 0.05 0" quat="1 1 0 0" size="0.04 0.07" />
              <body name="wrist_2_link" pos="0 0.127 0">
                <inertial mass="1.219" pos="0 0 0.1" diaginertia="0.0025599 0.0025599 0.0021942" />
                <joint name="wrist_2_joint" axis="0 0 1" />
                <site name="wrist_2_joint" />
                <geom mesh="wrist2_0" material="black" class="visual" />
                <geom mesh="wrist2_1" material="urblue" class="visual" />
                <geom mesh="wrist2_2" material="jointgray" class="visual" />
                <geom class="collision" size="0.04 0.06" pos="0 0 0.04" />
                <geom class="collision" pos="0 0.02 0.1" quat="1 1 0 0" size="0.04 0.04" />
                <body name="wrist_3_link" pos="0 0 0.1">
                  <inertial mass="0.1879" pos="0 0.0771683 0" quat="1 0 0 1"
                    diaginertia="0.000132134 9.90863e-05 9.90863e-05" />
                  <joint name="wrist_3_joint" />
                  <site name="wrist_3_joint" />
                  <geom material="linkgray" mesh="wrist3" class="visual" />
                  <geom class="eef_collision" pos="0 0.08 0" quat="1 1 0 0" size="0.04 0.02" />
                  <body name="attachment" pos="0 0.1 0" quat="-1 1 1 1">
                    <site name="attachment_site" rgba="1 0 0 1" size="0.01" group="1" />
                    <body name="base_mount" quat="1 0 0 1" childclass="2f85">
                      <geom class="2f85/visual" mesh="base_mount" material="2f85/black" />
                      <geom class="2f85/collision" mesh="base_mount" />
                      <body name="base" pos="0 0 0.0038" quat="1 0 0 -1">
                        <inertial mass="0.777441" pos="0 -2.70394e-05 0.0354675"
                          quat="1 -0.00152849 0 0"
                          diaginertia="0.000260285 0.000225381 0.000152708" />
                        <geom class="2f85/visual" mesh="base" material="2f85/black" />
                        <geom class="2f85/collision" mesh="base" />
                        <site name="pinch" pos="0 0 0.145" />
                        <body name="right_driver" pos="0 0.0306011 0.054904">
                          <inertial mass="0.00899563" pos="2.96931e-12 0.0177547 0.00107314"
                            quat="0.681301 0.732003 0 0"
                            diaginertia="1.72352e-06 1.60906e-06 3.22006e-07" />
                          <joint name="right_driver_joint" class="driver" />
                          <geom class="2f85/visual" mesh="driver" material="gray" />
                          <geom name="right_driver" class="2f85/collision" mesh="driver" />
                          <body name="right_coupler" pos="0 0.0315 -0.0041">
                            <inertial mass="0.0140974" pos="0 0.00301209 0.0232175"
                              quat="0.705636 -0.0455904 0.0455904 0.705636"
                              diaginertia="4.16206e-06 3.52216e-06 8.88131e-07" />
                            <joint name="right_coupler_joint" class="coupler" />
                            <geom class="2f85/visual" mesh="coupler" material="2f85/black" />
                            <geom class="2f85/collision" mesh="coupler" />
                          </body>
                        </body>
                        <body name="right_spring_link" pos="0 0.0132 0.0609">
                          <inertial mass="0.0221642" pos="-8.65005e-09 0.0181624 0.0212658"
                            quat="0.663403 -0.244737 0.244737 0.663403"
                            diaginertia="8.96853e-06 6.71733e-06 2.63931e-06" />
                          <joint name="right_spring_link_joint" class="spring_link" />
                          <geom class="2f85/visual" mesh="spring_link" material="2f85/black" />
                          <geom class="2f85/collision" mesh="spring_link" />
                          <body name="right_follower" pos="0 0.055 0.0375">
                            <inertial mass="0.0125222" pos="0 -0.011046 0.0124786"
                              quat="1 0.1664 0 0"
                              diaginertia="2.67415e-06 2.4559e-06 6.02031e-07" />
                            <joint name="right_follower_joint" class="follower" />
                            <body name="right_subassy" pos="0.09 0.02 0.24"
                              quat="0 0.707 0 -0.707">
                              <inertial
                                pos="0.0934020089723395 0.0157225552881997 0.0543562923281241"
                                mass="0.926217426305273"
                                diaginertia="7.62674421961674E-05 0.000277946035082107 0.000244957393107757" />
                              <geom
                                name="right_base_link_visual"
                                class="custom_gripper/visual"
                                mesh="right_base_link"
                                pos="0 0 0"
                                quat="1 0 0 0"
                                rgba="0.792156862745098 0.819607843137255 0.933333333333333 1" />
                              <geom
                                name="right_base_link_collision"
                                class="custom_gripper/collision"
                                mesh="right_base_link_collision"
                                pos="0 0 0"
                                quat="1 0 0 0"
                              />
                              <!-- Hook -->
                              <body name="hook_link" pos="0.042 0.009 0.053" quat="1 0 0 0">
                                <inertial
                                  pos="0.0100000000000002 0.05411684085681 -0.00324110579044801"
                                  mass="0.0113951382962291"
                                  diaginertia="1.05893195534218E-05 8.14301615510424E-07 1.05346938243266E-05" />
                                <geom
                                  name="hook_link_visual"
                                  class="custom_gripper/visual"
                                  mesh="hook_link"
                                  pos="0 0 0"
                                  quat="1 0 0 0"
                                  rgba="1 0.937254901960784 0.137254901960784 1"
                                />
                                <geom
                                  name="hook_link_collision"
                                  class="custom_gripper/collision"
                                  mesh="hook_link_collision"
                                  pos="0 0 0"
                                  quat="1 0 0 0"
                                />
                                <joint
                                  name="hook_joint"
                                  type="hinge"
                                  axis="-1 0 0"
                                  pos="0 0 0"
                                  range="0 0.62831" />
                              </body>
                            </body>
                          </body>
                        </body>
                        <body name="left_driver" pos="0 -0.0306011 0.054904" quat="0 0 0 1">
                          <inertial mass="0.00899563" pos="0 0.0177547 0.00107314"
                            quat="0.681301 0.732003 0 0"
                            diaginertia="1.72352e-06 1.60906e-06 3.22006e-07" />
                          <joint name="left_driver_joint" class="driver" />
                          <geom class="2f85/visual" mesh="driver" material="gray" />
                          <geom class="2f85/collision" mesh="driver" />
                          <body name="left_coupler" pos="0 0.0315 -0.0041">
                            <inertial mass="0.0140974" pos="0 0.00301209 0.0232175"
                              quat="0.705636 -0.0455904 0.0455904 0.705636"
                              diaginertia="4.16206e-06 3.52216e-06 8.88131e-07" />
                            <joint name="left_coupler_joint" class="coupler" />
                            <geom class="2f85/visual" mesh="coupler" material="2f85/black" />
                            <geom class="2f85/collision" mesh="coupler" />
                          </body>
                        </body>
                        <body name="left_spring_link" pos="0 -0.0132 0.0609" quat="0 0 0 1">
                          <inertial mass="0.0221642" pos="-8.65005e-09 0.0181624 0.0212658"
                            quat="0.663403 -0.244737 0.244737 0.663403"
                            diaginertia="8.96853e-06 6.71733e-06 2.63931e-06" />
                          <joint name="left_spring_link_joint" class="spring_link" />
                          <geom class="2f85/visual" mesh="spring_link" material="2f85/black" />
                          <geom class="2f85/collision" mesh="spring_link" />
                          <body name="left_follower" pos="0 0.055 0.0375">
                            <inertial mass="0.0125222" pos="0 -0.011046 0.0124786"
                              quat="1 0.1664 0 0"
                              diaginertia="2.67415e-06 2.4559e-06 6.02031e-07" />
                            <joint name="left_follower_joint" class="follower" />
                            <body name="left_subassy" pos="-0.09 0.02 0.24"
                              quat="-0.5 0.5 -0.5 0.5">
                              <inertial pos="0.022759520987878 0.090205428527215 0.0347712619150226"
                                mass="0.0955832510340183"
                                diaginertia="0.000343814638771794 0.00010368622496836 0.00029353692291537" />
                              <geom name="left_base_link_visual"
                                mesh="left_base_link"
                                class="custom_gripper/visual"
                                pos="0 0 0"
                                quat="1 0 0 0"
                                rgba="0.792156862745098 0.819607843137255 0.933333333333333 1" />
                              <geom name="left_base_link_collision"
                                mesh="left_base_link_collision"
                                class="custom_gripper/collision"
                                pos="0 0 0"
                                quat="1 0 0 0"
                              />
                            </body>
                          </body>
                        </body>
                      </body>
                    </body>
                  </body>
                </body>
              </body>
            </body>
          </body>
        </body>
      </body>
    </body>
  </worldbody>

  <contact>
    <exclude body1="base" body2="left_driver" />
    <exclude body1="base" body2="right_driver" />
    <exclude body1="base" body2="left_spring_link" />
    <exclude body1="base" body2="right_spring_link" />
    <exclude body1="right_coupler" body2="right_follower" />
    <exclude body1="left_coupler" body2="left_follower" />
  </contact>

  <tendon>
    <fixed name="split">
      <joint joint="right_driver_joint" coef="0.5" />
      <joint joint="left_driver_joint" coef="0.5" />
    </fixed>
  </tendon>

  <equality>
    <connect anchor="0 0 0" body1="right_follower" body2="right_coupler" solimp="0.95 0.99 0.001"
      solref="0.005 1" />
    <connect anchor="0 0 0" body1="left_follower" body2="left_coupler" solimp="0.95 0.99 0.001"
      solref="0.005 1" />
    <joint joint1="right_driver_joint" joint2="left_driver_joint" polycoef="0 1 0 0 0"
      solimp="0.95 0.99 0.001"
      solref="0.005 1" />
  </equality>

  <actuator>
    <position class="position" name="shoulder_pan_position" joint="shoulder_pan_joint" />
    <position class="position" name="shoulder_lift_position" joint="shoulder_lift_joint" />
    <position class="position_limited" name="elbow_position" joint="elbow_joint" />
    <position class="position_small" name="wrist_1_position" joint="wrist_1_joint" />
    <position class="position_small" name="wrist_2_position" joint="wrist_2_joint" />
    <position class="position_small" name="wrist_3_position" joint="wrist_3_joint" />
    <general class="2f85" name="fingers_actuator" tendon="split" forcerange="-15 15" ctrlrange="0 1"
      gainprm="80 0 0"
      biasprm="0 -100 -10" />
    <position class="hook" name="hook_position" joint="hook_joint" />
  </actuator>
</mujoco>